Traceback (most recent call last):
  File "/home/runner/workspace/main.py", line 863, in host_info
    await interaction.followup.send(card)
  File "/home/runner/workspace/.pythonlibs/lib/python3.10/site-packages/discord/webhook/async_.py", line 1843, in send
    data = await adapter.execute_webhook(
  File "/home/runner/workspace/.pythonlibs/lib/python3.10/site-packages/discord/webhook/async_.py", line 206, in request
    raise HTTPException(response, data)
discord.errors.HTTPException: 429 Too Many Requests (error code: 0): too many 4xx response codes, try again later


During handling of the above exception, another exception occurred:

Traceback (most recent call last):
  File "/home/runner/workspace/.pythonlibs/lib/python3.10/site-packages/discord/app_commands/commands.py", line 858, in _do_call
    return await self._callback(interaction, **params)  # type: ignore
  File "/home/runner/workspace/main.py", line 870, in host_info
    await interaction.response.send_message(f"‚ùå Une erreur est survenue : {str(e)}")
  File "/home/runner/workspace/.pythonlibs/lib/python3.10/site-packages/discord/interactions.py", line 855, in send_message
    await adapter.create_interaction_response(
  File "/home/runner/workspace/.pythonlibs/lib/python3.10/site-packages/discord/webhook/async_.py", line 206, in request
    raise HTTPException(response, data)
discord.errors.HTTPException: 429 Too Many Requests (error code: 0): too many 4xx response codes, try again later


The above exception was the direct cause of the following exception:

Traceback (most recent call last):
  File "/home/runner/workspace/.pythonlibs/lib/python3.10/site-packages/discord/app_commands/tree.py", line 1310, in _call
    await command._invoke_with_namespace(interaction, namespace)
  File "/home/runner/workspace/.pythonlibs/lib/python3.10/site-packages/discord/app_commands/commands.py", line 883, in _invoke_with_namespace
    return await self._do_call(interaction, transformed_values)
  File "/home/runner/workspace/.pythonlibs/lib/python3.10/site-packages/discord/app_commands/commands.py", line 876, in _do_call
    raise CommandInvokeError(self, e) from e
discord.app_commands.errors.CommandInvokeError: Command 'host_info' raised an exception: HTTPException: 429 Too Many Requests (error code: 0): too many 4xx response codes, try again later
